Workbook

Sheet 0) README & method
A1: PET nanoplastics (PET-NPs) Integrated assessment - Citarum basin, West Java (v1.0)
A2: Ecotoxicology + behaviour + risk assessment + EIA + screening LCA, one workbook
A5: Scope | B5: PET nanoplastics only (polystyrene excluded, as requested)
A6: Test material | B6: PET (polyethylene terephthalate) nanoplastics, d50 ~ 120 nm
A7: Study area | B7: Citarum river basin, Jawa Barat - highest composite PET pressure score of the provinces compared in sheet 2
A8: Test organisms | B8: Macrobrachium rosenbergii (small crustacean, PL-25) and Oreochromis niloticus (fish, juvenile)
A9: Modules | B9: 1 exposure characterisation | 2 ecotoxicology (dose-response, biomarkers, bioaccumulation) | 3 behavioural dynamics | 4 SSD/PNEC risk assessment | 5 EIA (Leopold + RIAM) | 6 screening LCA of PET | 7 integrated scorecard
A10: Functional unit (LCA) | B10: 1 kg PET bottle-grade resin, cradle-to-grave
A11: Impact method (LCA) | B11: IPCC GWP100 proxy factors, CED and water consumption; placeholder for a licensed ecoinvent dataset
A12: Risk method | B12: log-normal species sensitivity distribution -> HC5 -> PNEC = HC5 / AF(3); RQ = PEC95 / PNEC
A13: EIA method | B13: Leopold interaction matrix (magnitude x importance) and RIAM ES = (A1xA2)(B1+B2+B3)
A14: HONESTY NOTE | B14: Every number in this workbook is SYNTHETIC. It is a personal methodological demonstrator, not a field dataset. Nothing here should be cited as a measurement.
A15: How to reuse | B15: Replace sheet 3 (exposure) and sheet 4 (dose-response) with real data; all downstream sheets recompute through live formulas.
A16: Colour convention | B16: blue = editable input, black = formula, green = cross-sheet link, yellow = key assumption to check

Sheet 1) Parameters & sources
A1: Parameters, assumptions and status
A2: status column says whether a value is dummy, assumption, literature-anchored or derived
A3: Data status: synthetic (dummy) - generated, not measured
A5: parameter | B5: value | C5: unit | D5: role | E5: status | F5: note
A6: study_area | B6: Citarum river basin, Jawa Barat, Indonesia | C6: - | D6: case study boundary | E6: assumption | F6: chosen from the province ranking sheet
A7: polymer | B7: PET nanoplastics, d50 ~120 nm, spherical, PS excluded | C7: nm | D7: test material | E7: assumption | F7: matches the scope requested (PET only)
A8: n_stations | B8: 8 | C8: count | D8: sampling design | E8: dummy | F8: 8 stations, source to estuary
A9: seasons | B9: Kemarau (dry, Jul-Sep); Transisi (Apr-Jun/Oct); Hujan (wet, Dec-Feb) | C9: - | D9: sampling design | E9: dummy | F9: 3 hydrological seasons
A10: dose_series | B10: 0; 50; 250; 1,000; 5,000; 20,000 | C10: µg/L | D10: ecotox design | E10: dummy | F10: log-spaced, OECD-style geometric series
A11: exposure_duration | B11: 96 | C11: h | D11: ecotox design | E11: assumption | F11: acute, semi-static, 24 h renewal
A12: replicates | B12: 4 | C12: count | D12: ecotox design | E12: assumption | F12: 20 organisms per replicate
A13: lc50_MRO | B13: 1850 | C13: µg/L | D13: Macrobrachium rosenbergii nominal LC50 | E13: dummy | F13: generating parameter of the synthetic dose-response
A14: ec50_growth_MRO | B14: 610 | C14: µg/L | D14: Macrobrachium rosenbergii nominal growth EC50 | E14: dummy | F14: generating parameter
A15: lc50_ONI | B15: 6400 | C15: µg/L | D15: Oreochromis niloticus nominal LC50 | E15: dummy | F15: generating parameter of the synthetic dose-response
A16: ec50_growth_ONI | B16: 1950 | C16: µg/L | D16: Oreochromis niloticus nominal growth EC50 | E16: dummy | F16: generating parameter
A17: ssd_n_species | B17: 12 | C17: count | D17: SSD | E17: mixed | F17: 8 taxonomic groups
A18: hc5 | B18: 100.39 | C18: µg/L | D18: SSD 5th percentile | E18: derived | F18: log-normal fit
A19: assessment_factor | B19: 3 | C19: - | D19: PNEC derivation | E19: assumption | F19: AF 3 because an SSD with >=8 species is available
A20: pnec | B20: 33.465 | C20: µg/L | D20: PNEC | E20: derived | F20: HC5 / AF
A21: rq_threshold | B21: 1 | C21: - | D21: risk classification | E21: convention | F21: ECHA R.10 style banding
A22: grid_emission_factor | B22: 0.79 | C22: kg CO2e/kWh | D22: LCA background | E22: literature-anchored | F22: Jamali grid, replace with the licensed dataset value
A23: lca_functional_unit | B23: 1 kg PET bottle-grade resin, cradle-to-grave | C23: - | D23: LCA scope | E23: assumption | F23: screening level, proxy factors only
A24: eol_scenarios | B24: S0 Business as usual (2024 baseline); S1 Improved collection (Citarum Harum target); S2 EPR + bottle-to-bottle recycling; S3 Full containment (upper bound) | C24: - | D24: LCA scenarios | E24: dummy | F24: collection and leakage variants
A25: integrated_weights | B25: ecotox 0.30 / risk 0.35 / EIA 0.20 / exposure 0.15 | C25: - | D25: scorecard | E25: assumption | F25: editable in sheet 14

Sheet 2) Province ranking
A1: Province-level PET exposure pressure - why Jawa Barat (West Java) ??
A2: score = 0.40 river plastic flux + 0.30 PET in waste + 0.20 converter plants + 0.10 population density
A3: Data status: synthetic (dummy) - generated, not measured
A5: rank | B5: province | C5: msw_generation_kt_yr | D5: plastic_share_pct | E5: pet_share_of_plastic_pct | F5: textile_and_bottling_plants_n | G5: population_density_p_km2 | H5: river_plastic_flux_index | I5: pet_in_waste_kt_yr | J5: exposure_pressure_score
A6: 1 | B6: Jawa Barat | C6: 6520 | D6: 17.8 | E6: 22.5 | F6: 1180 | G6: 1450 | H6: 100 | I6: 261.13 | J6: 90.9
A7: 2 | B7: DKI Jakarta | C7: 3180 | D7: 19.4 | E7: 24.1 | F7: 410 | G7: 15900 | H7: 88.5 | I7: 148.68 | J7: 69.4
A8: 3 | B8: Jawa Timur | C8: 5480 | D8: 16.2 | E8: 20.3 | F8: 860 | G8: 850 | H8: 76.4 | I8: 180.22 | J8: 66.4
A9: 4 | B9: Jawa Tengah | C9: 4720 | D9: 15.6 | E9: 19.8 | F9: 640 | G9: 1060 | H9: 68.1 | I9: 145.79 | J9: 55.5
A10: 5 | B10: Banten | C10: 2140 | D10: 17.1 | E10: 21.6 | F10: 520 | G10: 1320 | H10: 61.7 | I10: 79.04 | J10: 43.4
A11: 6 | B11: Sumatera Utara | C11: 2280 | D11: 14.3 | E11: 18.4 | F11: 210 | G11: 200 | H11: 44.2 | I11: 59.99 | J11: 28.3
A12: 7 | B12: Bali | C12: 940 | D12: 18.2 | E12: 21 | F12: 130 | G12: 750 | H12: 39.8 | I12: 35.93 | J12: 22.7

Sheet 3) Stations & exposure
A1: Sampling stations and measured PET nanoplastic exposure
A2: 8 stations from Situ Cisanti to Muara Gembong x 3 seasons x 3 field replicates
A3: Data status: synthetic (dummy) - generated, not measured
A5: station_code | B5: station_name | C5: regency | D5: river_km | E5: pressure_type | F5: population_density_p_km2 | G5: latitude_dd | H5: longitude_dd | I5: water_body
A6: ST1 | B6: Situ Cisanti (headwater) | C6: Kab. Bandung | D6: 0 | E6: reference / upstream forest | F6: 420 | G6: -7.204 | H6: 107.663 | I6: lake/spring
A7: ST2 | B7: Majalaya (textile cluster) | C7: Kab. Bandung | D7: 32 | E7: textile wastewater | F7: 3900 | G7: -7.048 | H7: 107.76 | I7: river
A8: ST3 | B8: Dayeuhkolot | C8: Kab. Bandung | D8: 54 | E8: urban domestic + industry | F8: 8600 | G8: -6.983 | H8: 107.618 | I8: river
A9: ST4 | B9: Nanjung - Bandung Barat | C9: Kab. Bandung Barat | D9: 71 | E9: mixed urban runoff | F9: 5100 | G9: -6.928 | H9: 107.55 | I9: river
A10: ST5 | B10: Saguling reservoir inlet | C10: Kab. Bandung Barat | D10: 95 | E10: reservoir sedimentation | F10: 1400 | G10: -6.912 | H10: 107.38 | I10: reservoir inlet
A11: ST6 | B11: Cirata reservoir | C11: Kab. Purwakarta | D11: 128 | E11: reservoir + aquaculture cages | F11: 1100 | G11: -6.703 | H11: 107.31 | I11: reservoir
A12: ST7 | B12: Jatiluhur outlet | C12: Kab. Purwakarta | D12: 158 | E12: reservoir outlet / raw water intake | F12: 1600 | G12: -6.535 | H12: 107.386 | I12: reservoir outlet
A13: ST8 | B13: Muara Gembong (estuary) | C13: Kab. Bekasi | D13: 269 | E13: estuary, landfill leachate + tidal | F13: 2300 | G13: -5.977 | H13: 107.014 | I13: estuary
A15: Exposure records (blue = replace with measured data)
A16: station_code | B16: station_name | C16: regency | D16: river_km | E16: season | F16: replicate | G16: pet_np_water_ug_L | H16: pet_np_particles_per_L | I16: d50_nm | J16: zeta_potential_mV | K16: tss_mg_L | L16: pet_np_sediment_mg_kg | M16: dissolved_organic_carbon_mg_L | N16: water_temp_C | O16: pH | P16: season_note | Q16: data_status
A17: ST1 | B17: Situ Cisanti (headwater) | C17: Kab. Bandung | D17: 0 | E17: Kemarau (dry, Jul-Sep) | F17: 1 | G17: 0.83 | H17: 1539349 | I17: 78.2 | J17: -23.2 | K17: 10.6 | L17: 1.11 | M17: 6.8 | N17: 25.8 | O17: 6.94 | P17: low flow, less dilution but less land wash-off | Q17: synthetic (dummy) - generated, not measured
A18: ST1 | B18: Situ Cisanti (headwater) | C18: Kab. Bandung | D18: 0 | E18: Kemarau (dry, Jul-Sep) | F18: 2 | G18: 0.93 | H18: 1919029 | I18: 107.4 | J18: -24.5 | K18: 5.9 | L18: 1.22 | M18: 5.99 | N18: 27.1 | O18: 7.62 | P18: low flow, less dilution but less land wash-off | Q18: synthetic (dummy) - generated, not measured
A19: ST1 | B19: Situ Cisanti (headwater) | C19: Kab. Bandung | D19: 0 | E19: Kemarau (dry, Jul-Sep) | F19: 3 | G19: 0.91 | H19: 1754010 | I19: 94.7 | J19: -29.4 | K19: 6.4 | L19: 0.9 | M19: 3.48 | N19: 28.2 | O19: 7.03 | P19: low flow, less dilution but less land wash-off | Q19: synthetic (dummy) - generated, not measured
A20: ST1 | B20: Situ Cisanti (headwater) | C20: Kab. Bandung | D20: 0 | E20: Transisi (Apr-Jun/Oct) | F20: 1 | G20: 0.79 | H20: 1554894 | I20: 97.7 | J20: -25.5 | K20: 16.2 | L20: 1.19 | M20: 6.87 | N20: 26.6 | O20: 7.76 | P20: reference season for PEC | Q20: synthetic (dummy) - generated, not measured
A21: ST1 | B21: Situ Cisanti (headwater) | C21: Kab. Bandung | D21: 0 | E21: Transisi (Apr-Jun/Oct) | F21: 2 | G21: 1.23 | H21: 2825225 | I21: 90.7 | J21: -21.4 | K21: 13.8 | L21: 1.2 | M21: 4.65 | N21: 27 | O21: 7.15 | P21: reference season for PEC | Q21: synthetic (dummy) - generated, not measured
A22: ST1 | B22: Situ Cisanti (headwater) | C22: Kab. Bandung | D22: 0 | E22: Transisi (Apr-Jun/Oct) | F22: 3 | G22: 0.92 | H22: 1764148 | I22: 94.5 | J22: -25.3 | K22: 14 | L22: 0.92 | M22: 5.05 | N22: 29 | O22: 7.16 | P22: reference season for PEC | Q22: synthetic (dummy) - generated, not measured
A23: ST1 | B23: Situ Cisanti (headwater) | C23: Kab. Bandung | D23: 0 | E23: Hujan (wet, Dec-Feb) | F23: 1 | G23: 1.25 | H23: 2179601 | I23: 96.1 | J23: -24.9 | K23: 28 | L23: 1.58 | M23: 4.09 | N23: 27.1 | O23: 7.2 | P23: runoff-driven mobilisation of PET debris | Q23: synthetic (dummy) - generated, not measured
A24: ST1 | B24: Situ Cisanti (headwater) | C24: Kab. Bandung | D24: 0 | E24: Hujan (wet, Dec-Feb) | F24: 2 | G24: 1.14 | H24: 2193736 | I24: 72.3 | J24: -20.3 | K24: 32.5 | L24: 1.03 | M24: 7.83 | N24: 27.9 | O24: 7.8 | P24: runoff-driven mobilisation of PET debris | Q24: synthetic (dummy) - generated, not measured
A25: ST1 | B25: Situ Cisanti (headwater) | C25: Kab. Bandung | D25: 0 | E25: Hujan (wet, Dec-Feb) | F25: 3 | G25: 1.63 | H25: 2945011 | I25: 89.4 | J25: -24 | K25: 34.5 | L25: 2.15 | M25: 6.3 | N25: 27.4 | O25: 7.24 | P25: runoff-driven mobilisation of PET debris | Q25: synthetic (dummy) - generated, not measured
A26: ST2 | B26: Majalaya (textile cluster) | C26: Kab. Bandung | D26: 32 | E26: Kemarau (dry, Jul-Sep) | F26: 1 | G26: 24.72 | H26: 49910946 | I26: 103.3 | J26: -29.6 | K26: 26.9 | L26: 23.37 | M26: 4.86 | N26: 29.7 | O26: 7 | P26: low flow, less dilution but less land wash-off | Q26: synthetic (dummy) - generated, not measured
A27: ST2 | B27: Majalaya (textile cluster) | C27: Kab. Bandung | D27: 32 | E27: Kemarau (dry, Jul-Sep) | F27: 2 | G27: 24.18 | H27: 43290596 | I27: 112.2 | J27: -22.8 | K27: 29 | L27: 37.1 | M27: 7.26 | N27: 28.1 | O27: 7.26 | P27: low flow, less dilution but less land wash-off | Q27: synthetic (dummy) - generated, not measured
A28: ST2 | B28: Majalaya (textile cluster) | C28: Kab. Bandung | D28: 32 | E28: Kemarau (dry, Jul-Sep) | F28: 3 | G28: 26.43 | H28: 55781068 | I28: 121.5 | J28: -23.2 | K28: 22.9 | L28: 31.99 | M28: 9.45 | N28: 28.7 | O28: 7.43 | P28: low flow, less dilution but less land wash-off | Q28: synthetic (dummy) - generated, not measured
... A88: ST8 | B88: Muara Gembong (estuary) | C88: Kab. Bekasi | D88: 269 | E88: Hujan (wet, Dec-Feb) | F88: 3 | G88: 36.08 | H88: 62673143 | I88: 88.1 | J88: -22.5 | K88: 64.8 | L88: 38.64 | M88: 8.72 | N88: 27.8 | O88: 7.09 | P88: runoff-driven mobilisation of PET debris | Q88: synthetic (dummy) - generated, not measured
A90: Mean PET NP in water per station and season (µg/L) - live AVERAGEIFS over the table above
A91: station_code | B91: Kemarau (dry, Jul-Sep) | C91: Transisi (Apr-Jun/Oct) | D91: Hujan (wet, Dec-Feb)
A92: ST1 | B92: =AVERAGEIFS(G17:G88,A17:A88,$A92,E17:E88,B$91) -> 0.89 | C92: =AVERAGEIFS(G17:G88,A17:A88,$A92,E17:E88,C$91) -> 0.98 | D92: =AVERAGEIFS(G17:G88,A17:A88,$A92,E17:E88,D$91) -> 1.34
A93: ST2 | B93: =AVERAGEIFS(G17:G88,A17:A88,$A93,E17:E88,B$91) -> 25.11 | C93: =AVERAGEIFS(G17:G88,A17:A88,$A93,E17:E88,C$91) -> 38.103333 | D93: =AVERAGEIFS(G17:G88,A17:A88,$A93,E17:E88,D$91) -> 46.346667
A94: ST3 | B94: =AVERAGEIFS(G17:G88,A17:A88,$A94,E17:E88,B$91) -> 41.01 | C94: =AVERAGEIFS(G17:G88,A17:A88,$A94,E17:E88,C$91) -> 50.426667 | D94: =AVERAGEIFS(G17:G88,A17:A88,$A94,E17:E88,D$91) -> 60.606667
A95: ST4 | B95: =AVERAGEIFS(G17:G88,A17:A88,$A95,E17:E88,B$91) -> 20.433333 | C95: =AVERAGEIFS(G17:G88,A17:A88,$A95,E17:E88,C$91) -> 26.493333 | D95: =AVERAGEIFS(G17:G88,A17:A88,$A95,E17:E88,D$91) -> 42.51
A96: ST5 | B96: =AVERAGEIFS(G17:G88,A17:A88,$A96,E17:E88,B$91) -> 12.616667 | C96: =AVERAGEIFS(G17:G88,A17:A88,$A96,E17:E88,C$91) -> 20.686667 | D96: =AVERAGEIFS(G17:G88,A17:A88,$A96,E17:E88,D$91) -> 26.106667
A97: ST6 | B97: =AVERAGEIFS(G17:G88,A17:A88,$A97,E17:E88,B$91) -> 8.6233333 | C97: =AVERAGEIFS(G17:G88,A17:A88,$A97,E17:E88,C$91) -> 12.453333 | D97: =AVERAGEIFS(G17:G88,A17:A88,$A97,E17:E88,D$91) -> 22.63
A98: ST7 | B98: =AVERAGEIFS(G17:G88,A17:A88,$A98,E17:E88,B$91) -> 6.0466667 | C98: =AVERAGEIFS(G17:G88,A17:A88,$A98,E17:E88,C$91) -> 9.4966667 | D98: =AVERAGEIFS(G17:G88,A17:A88,$A98,E17:E88,D$91) -> 12.896667
A99: ST8 | B99: =AVERAGEIFS(G17:G88,A17:A88,$A99,E17:E88,B$91) -> 14.736667 | C99: =AVERAGEIFS(G17:G88,A17:A88,$A99,E17:E88,C$91) -> 26.006667 | D99: =AVERAGEIFS(G17:G88,A17:A88,$A99,E17:E88,D$91) -> 32.15

Sheet 4) Ecotox dose-response
A1: Dose-response, 96 h, PET nanoplastics
A2: LC50 / EC50 are computed with Excel formulas (log-logit regression), not hardcoded
A3: Data status: synthetic (dummy) - generated, not measured
A5: species | B5: species_code | C5: group | D5: life_stage | E5: dose_pet_np_ug_L | F5: replicate | G5: n_organisms | H5: mortality_96h_pct | I5: growth_inhibition_pct | J5: third_endpoint_name | K5: third_endpoint_pct | L5: exposure_h | M5: medium
A6: Macrobrachium rosenbergii | B6: MRO | C6: small crustacean | D6: post-larvae PL-25 | E6: 0 | F6: 1 | G6: 20 | H6: 0 | I6: 1.62 | J6: moulting_delay_pct | K6: -2.57 | L6: 96 | M6: dechlorinated tap water, semi-static renewal 24 h
A7: Macrobrachium rosenbergii | B7: MRO | C7: small crustacean | D7: post-larvae PL-25 | E7: 0 | F7: 2 | G7: 20 | H7: 0 | I7: -0.97 | J7: moulting_delay_pct | K7: 1.59 | L7: 96 | M7: dechlorinated tap water, semi-static renewal 24 h
A8: Macrobrachium rosenbergii | B8: MRO | C8: small crustacean | D8: post-larvae PL-25 | E8: 0 | F8: 3 | G8: 20 | H8: 3.78 | I8: 2.16 | J8: moulting_delay_pct | K8: -0.37 | L8: 96 | M8: dechlorinated tap water, semi-static renewal 24 h
A9: Macrobrachium rosenbergii | B9: MRO | C9: small crustacean | D9: post-larvae PL-25 | E9: 0 | F9: 4 | G9: 20 | H9: 0 | I9: -1.75 | J9: moulting_delay_pct | K9: -0.09 | L9: 96 | M9: dechlorinated tap water, semi-static renewal 24 h
A10: Macrobrachium rosenbergii | B10: MRO | C10: small crustacean | D10: post-larvae PL-25 | E10: 50 | F10: 1 | G10: 20 | H10: 2.44 | I10: 2.07 | J10: moulting_delay_pct | K10: 2.35 | L10: 96 | M10: dechlorinated tap water, semi-static renewal 24 h
A11: Macrobrachium rosenbergii | B11: MRO | C11: small crustacean | D11: post-larvae PL-25 | E11: 50 | F11: 2 | G11: 20 | H11: 0 | I11: 7.27 | J11: moulting_delay_pct | K11: 8.08 | L11: 96 | M11: dechlorinated tap water, semi-static renewal 24 h
A12: Macrobrachium rosenbergii | B12: MRO | C12: small crustacean | D12: post-larvae PL-25 | E12: 50 | F12: 3 | G12: 20 | H12: 0.19 | I12: 5.67 | J12: moulting_delay_pct | K12: 1.76 | L12: 96 | M12: dechlorinated tap water, semi-static renewal 24 h
A13: Macrobrachium rosenbergii | B13: MRO | C13: small crustacean | D13: post-larvae PL-25 | E13: 50 | F13: 4 | G13: 20 | H13: 0 | I13: 1.7 | J13: moulting_delay_pct | K13: 1.52 | L13: 96 | M13: dechlorinated tap water, semi-static renewal 24 h
A14: Macrobrachium rosenbergii | B14: MRO | C14: small crustacean | D14: post-larvae PL-25 | E14: 250 | F14: 1 | G14: 20 | H14: 1.87 | I14: 20.79 | J14: moulting_delay_pct | K14: 13.44 | L14: 96 | M14: dechlorinated tap water, semi-static renewal 24 h
A15: Macrobrachium rosenbergii | B15: MRO | C15: small crustacean | D15: post-larvae PL-25 | E15: 250 | F15: 2 | G15: 20 | H15: 4.76 | I15: 19.35 | J15: moulting_delay_pct | K15: 18.96 | L15: 96 | M15: dechlorinated tap water, semi-static renewal 24 h
A16: Macrobrachium rosenbergii | B16: MRO | C16: small crustacean | D16: post-larvae PL-25 | E16: 250 | F16: 3 | G16: 20 | H16: 3.13 | I16: 23.11 | J16: moulting_delay_pct | K16: 16.11 | L16: 96 | M16: dechlorinated tap water, semi-static renewal 24 h
A17: Macrobrachium rosenbergii | B17: MRO | C17: small crustacean | D17: post-larvae PL-25 | E17: 250 | F17: 4 | G17: 20 | H17: 11.27 | I17: 22.99 | J17: moulting_delay_pct | K17: 15.31 | L17: 96 | M17: dechlorinated tap water, semi-static renewal 24 h
... A53: Oreochromis niloticus | B53: ONI | C53: fish | D53: juvenile 2.1 +/- 0.3 g | E53: 20000 | F53: 4 | G53: 20 | H53: 83.86 | I53: 73.48 | J53: gill_histopathology_index | K53: 48.88 | L53: 96 | M53: dechlorinated tap water, semi-static renewal 24 h
A56: Regression block - Macrobrachium rosenbergii
A57: dose (µg/L) | B57: log10(dose) | C57: mean mortality % | D57: logit(mortality) | E57: mean growth inhib. % | F57: logit(growth) | G57: mean 3rd endpoint % | H57: logit(3rd)
A58: 50 | B58: =LOG10(A58) -> 1.69897 | C58: =AVERAGEIFS(H$6:H$53,A$6:A$53,"Macrobrachium rosenbergii",E$6:E$53,$A58) -> 0.6575 | D58: =LN(MAX(MIN(C58,100-0.5),0.5)/(100-MAX(MIN(C58,100-0.5),0.5))) -> -5.017884 | E58: =AVERAGEIFS(I$6:I$53,A$6:A$53,"Macrobrachium rosenbergii",E$6:E$53,$A58) -> 4.1775 | F58: =LN(MAX(MIN(E58,82-0.5),0.5)/(82-MAX(MIN(E58,82-0.5),0.5))) -> -2.9247176 | G58: =AVERAGEIFS(K$6:K$53,A$6:A$53,"Macrobrachium rosenbergii",E$6:E$53,$A58) -> 3.4275 | H58: =LN(MAX(MIN(G58,70-0.5),0.5)/(70-MAX(MIN(G58,70-0.5),0.5))) -> -2.9664604
A59: 250 | B59: =LOG10(A59) -> 2.39794 | C59: =AVERAGEIFS(H$6:H$53,A$6:A$53,"Macrobrachium rosenbergii",E$6:E$53,$A59) -> 5.2575 | D59: =LN(MAX(MIN(C59,100-0.5),0.5)/(100-MAX(MIN(C59,100-0.5),0.5))) -> -2.8915071 | E59: =AVERAGEIFS(I$6:I$53,A$6:A$53,"Macrobrachium rosenbergii",E$6:E$53,$A59) -> 21.56 | F59: =LN(MAX(MIN(E59,82-0.5),0.5)/(82-MAX(MIN(E59,82-0.5),0.5))) -> -1.0308114 | G59: =AVERAGEIFS(K$6:K$53,A$6:A$53,"Macrobrachium rosenbergii",E$6:E$53,$A59) -> 15.955 | H59: =LN(MAX(MIN(G59,70-0.5),0.5)/(70-MAX(MIN(G59,70-0.5),0.5))) -> -1.2200448
A60: 1000 | B60: =LOG10(A60) -> 3 | C60: =AVERAGEIFS(H$6:H$53,A$6:A$53,"Macrobrachium rosenbergii",E$6:E$53,$A60) -> 29.775 | D60: =LN(MAX(MIN(C60,100-0.5),0.5)/(100-MAX(MIN(C60,100-0.5),0.5))) -> -0.85803526 | E60: =AVERAGEIFS(I$6:I$53,A$6:A$53,"Macrobrachium rosenbergii",E$6:E$53,$A60) -> 50.6325 | F60: =LN(MAX(MIN(E60,82-0.5),0.5)/(82-MAX(MIN(E60,82-0.5),0.5))) -> 0.47882134 | G60: =AVERAGEIFS(K$6:K$53,A$6:A$53,"Macrobrachium rosenbergii",E$6:E$53,$A60) -> 32.7325 | H60: =LN(MAX(MIN(G60,70-0.5),0.5)/(70-MAX(MIN(G60,70-0.5),0.5))) -> -0.12975317
A61: 5000 | B61: =LOG10(A61) -> 3.69897 | C61: =AVERAGEIFS(H$6:H$53,A$6:A$53,"Macrobrachium rosenbergii",E$6:E$53,$A61) -> 81.975 | D61: =LN(MAX(MIN(C61,100-0.5),0.5)/(100-MAX(MIN(C61,100-0.5),0.5))) -> 1.5146546 | E61: =AVERAGEIFS(I$6:I$53,A$6:A$53,"Macrobrachium rosenbergii",E$6:E$53,$A61) -> 70.3875 | F61: =LN(MAX(MIN(E61,82-0.5),0.5)/(82-MAX(MIN(E61,82-0.5),0.5))) -> 1.8019336 | G61: =AVERAGEIFS(K$6:K$53,A$6:A$53,"Macrobrachium rosenbergii",E$6:E$53,$A61) -> 52.805 | H61: =LN(MAX(MIN(G61,70-0.5),0.5)/(70-MAX(MIN(G61,70-0.5),0.5))) -> 1.1219872
A62: 20000 | B62: =LOG10(A62) -> 4.30103 | C62: =AVERAGEIFS(H$6:H$53,A$6:A$53,"Macrobrachium rosenbergii",E$6:E$53,$A62) -> 93.705 | D62: =LN(MAX(MIN(C62,100-0.5),0.5)/(100-MAX(MIN(C62,100-0.5),0.5))) -> 2.7003959 | E62: =AVERAGEIFS(I$6:I$53,A$6:A$53,"Macrobrachium rosenbergii",E$6:E$53,$A62) -> 75.96 | F62: =LN(MAX(MIN(E62,82-0.5),0.5)/(82-MAX(MIN(E62,82-0.5),0.5))) -> 2.5318029 | G62: =AVERAGEIFS(K$6:K$53,A$6:A$53,"Macrobrachium rosenbergii",E$6:E$53,$A62) -> 59.8275 | H62: =LN(MAX(MIN(G62,70-0.5),0.5)/(70-MAX(MIN(G62,70-0.5),0.5))) -> 1.7717774
A64: LC50 mortality (µg/L) | C64: =10^(-INTERCEPT(D58:D62,$B$58:$B$62)/SLOPE(D58:D62,$B$58:$B$62)) -> 2077.6375 | D64: =RSQ(D58:D62,$B$58:$B$62) -> 0.99397682 | E64: Hill slope | F64: =SLOPE(D58:D62,$B$58:$B$62) -> 3.0533618
A65: EC50 growth (µg/L) | C65: =10^(-INTERCEPT(F58:F62,$B$58:$B$62)/SLOPE(F58:F62,$B$58:$B$62)) -> 867.75818 | D65: =RSQ(F58:F62,$B$58:$B$62) -> 0.98005451 | E65: Hill slope | F65: =SLOPE(F58:F62,$B$58:$B$62) -> 2.1165573
A66: EC50 3rd endpoint (µg/L) | C66: =10^(-INTERCEPT(H58:H62,$B$58:$B$62)/SLOPE(H58:H62,$B$58:$B$62)) -> 1498.3611 | D66: =RSQ(H58:H62,$B$58:$B$62) -> 0.98201343 | E66: Hill slope | F66: =SLOPE(H58:H62,$B$58:$B$62) -> 1.8209726
A67: Method: log-logistic linearised as logit(response) = a*log10(dose) + b; EC50 = 10^(-b/a).
A70: Regression block - Oreochromis niloticus
A71: dose (µg/L) | B71: log10(dose) | C71: mean mortality % | D71: logit(mortality) | E71: mean growth inhib. % | F71: logit(growth) | G71: mean 3rd endpoint % | H71: logit(3rd)
A72: 50 | B72: =LOG10(A72) -> 1.69897 | C72: =AVERAGEIFS(H$6:H$53,A$6:A$53,"Oreochromis niloticus",E$6:E$53,$A72) -> 1.92 | D72: =LN(MAX(MIN(C72,100-0.5),0.5)/(100-MAX(MIN(C72,100-0.5),0.5))) -> -3.9334583 | E72: =AVERAGEIFS(I$6:I$53,A$6:A$53,"Oreochromis niloticus",E$6:E$53,$A72) -> 0.69 | F72: =LN(MAX(MIN(E72,82-0.5),0.5)/(82-MAX(MIN(E72,82-0.5),0.5))) -> -4.7693327 | G72: =AVERAGEIFS(K$6:K$53,A$6:A$53,"Oreochromis niloticus",E$6:E$53,$A72) -> 1.29 | H72: =LN(MAX(MIN(G72,70-0.5),0.5)/(70-MAX(MIN(G72,70-0.5),0.5))) -> -3.9752525
A73: 250 | B73: =LOG10(A73) -> 2.39794 | C73: =AVERAGEIFS(H$6:H$53,A$6:A$53,"Oreochromis niloticus",E$6:E$53,$A73) -> 1.48 | D73: =LN(MAX(MIN(C73,100-0.5),0.5)/(100-MAX(MIN(C73,100-0.5),0.5))) -> -4.1982175 | E73: =AVERAGEIFS(I$6:I$53,A$6:A$53,"Oreochromis niloticus",E$6:E$53,$A73) -> 9.425 | F73: =LN(MAX(MIN(E73,82-0.5),0.5)/(82-MAX(MIN(E73,82-0.5),0.5))) -> -2.0412548 | G73: =AVERAGEIFS(K$6:K$53,A$6:A$53,"Oreochromis niloticus",E$6:E$53,$A73) -> 4.1775 | H73: =LN(MAX(MIN(G73,70-0.5),0.5)/(70-MAX(MIN(G73,70-0.5),0.5))) -> -2.7572487
A74: 1000 | B74: =LOG10(A74) -> 3 | C74: =AVERAGEIFS(H$6:H$53,A$6:A$53,"Oreochromis niloticus",E$6:E$53,$A74) -> 10.22 | D74: =LN(MAX(MIN(C74,100-0.5),0.5)/(100-MAX(MIN(C74,100-0.5),0.5))) -> -2.1730156 | E74: =AVERAGEIFS(I$6:I$53,A$6:A$53,"Oreochromis niloticus",E$6:E$53,$A74) -> 25.47 | F74: =LN(MAX(MIN(E74,82-0.5),0.5)/(82-MAX(MIN(E74,82-0.5),0.5))) -> -0.79727018 | G74: =AVERAGEIFS(K$6:K$53,A$6:A$53,"Oreochromis niloticus",E$6:E$53,$A74) -> 12.8175 | H74: =LN(MAX(MIN(G74,70-0.5),0.5)/(70-MAX(MIN(G74,70-0.5),0.5))) -> -1.4954365
A75: 5000 | B75: =LOG10(A75) -> 3.69897 | C75: =AVERAGEIFS(H$6:H$53,A$6:A$53,"Oreochromis niloticus",E$6:E$53,$A75) -> 44.885 | D75: =LN(MAX(MIN(C75,100-0.5),0.5)/(100-MAX(MIN(C75,100-0.5),0.5))) -> -0.20531825 | E75: =AVERAGEIFS(I$6:I$53,A$6:A$53,"Oreochromis niloticus",E$6:E$53,$A75) -> 56.9125 | F75: =LN(MAX(MIN(E75,82-0.5),0.5)/(82-MAX(MIN(E75,82-0.5),0.5))) -> 0.81914529 | G75: =AVERAGEIFS(K$6:K$53,A$6:A$53,"Oreochromis niloticus",E$6:E$53,$A75) -> 38.67 | H75: =LN(MAX(MIN(G75,70-0.5),0.5)/(70-MAX(MIN(G75,70-0.5),0.5))) -> 0.210488
A76: 20000 | B76: =LOG10(A76) -> 4.30103 | C76: =AVERAGEIFS(H$6:H$53,A$6:A$53,"Oreochromis niloticus",E$6:E$53,$A76) -> 80.4525 | D76: =LN(MAX(MIN(C76,100-0.5),0.5)/(100-MAX(MIN(C76,100-0.5),0.5))) -> 1.4148195 | E76: =AVERAGEIFS(I$6:I$53,A$6:A$53,"Oreochromis niloticus",E$6:E$53,$A76) -> 70.7925 | F76: =LN(MAX(MIN(E76,82-0.5),0.5)/(82-MAX(MIN(E76,82-0.5),0.5))) -> 1.8431699 | G76: =AVERAGEIFS(K$6:K$53,A$6:A$53,"Oreochromis niloticus",E$6:E$53,$A76) -> 47.12 | H76: =LN(MAX(MIN(G76,70-0.5),0.5)/(70-MAX(MIN(G76,70-0.5),0.5))) -> 0.72243437
A78: LC50 mortality (µg/L) | C78: =10^(-INTERCEPT(D72:D76,$B$72:$B$76)/SLOPE(D72:D76,$B$72:$B$76)) -> 6739.2418 | D78: =RSQ(D72:D76,$B$72:$B$76) -> 0.91757975 | E78: Hill slope | F78: =SLOPE(D72:D76,$B$72:$B$76) -> 2.2478655
A79: EC50 growth (µg/L) | C79: =10^(-INTERCEPT(F72:F76,$B$72:$B$76)/SLOPE(F72:F76,$B$72:$B$76)) -> 2619.7524 | D79: =RSQ(F72:F76,$B$72:$B$76) -> 0.97428308 | E79: Hill slope | F79: =SLOPE(F72:F76,$B$72:$B$76) -> 2.4797254
A80: EC50 3rd endpoint (µg/L) | C80: =10^(-INTERCEPT(H72:H76,$B$72:$B$76)/SLOPE(H72:H76,$B$72:$B$76)) -> 6107.5707 | D80: =RSQ(H72:H76,$B$72:$B$76) -> 0.98578378 | E80: Hill slope | F80: =SLOPE(H72:H76,$B$72:$B$76) -> 1.9034948
A81: Method: log-logistic linearised as logit(response) = a*log10(dose) + b; EC50 = 10^(-b/a).

Sheet 5) Biomarkers
A1: Oxidative stress and neurotoxicity biomarkers
A2: hepatopancreas (crustacean) / liver (fish); fold change relative to the unexposed control
A3: Data status: synthetic (dummy) - generated, not measured
A5: species | B5: species_code | C5: dose_pet_np_ug_L | D5: replicate | E5: biomarker | F5: value | G5: control_mean | H5: fold_change_vs_control | I5: tissue | J5: interpretation
A6: Macrobrachium rosenbergii | B6: MRO | C6: 0 | D6: 1 | E6: SOD_U_per_mg_protein | F6: 18.391 | G6: 18.5 | H6: 1 | I6: hepatopancreas | J6: oxidative defence, biphasic
A7: Macrobrachium rosenbergii | B7: MRO | C7: 0 | D7: 2 | E7: SOD_U_per_mg_protein | F7: 21.098 | G7: 18.5 | H7: 1 | I7: hepatopancreas | J7: oxidative defence, biphasic
A8: Macrobrachium rosenbergii | B8: MRO | C8: 0 | D8: 3 | E8: SOD_U_per_mg_protein | F8: 19.579 | G8: 18.5 | H8: 1 | I8: hepatopancreas | J8: oxidative defence, biphasic
A9: Macrobrachium rosenbergii | B9: MRO | C9: 0 | D9: 1 | E9: CAT_U_per_mg_protein | F9: 26.797 | G9: 24 | H9: 1 | I9: hepatopancreas | J9: oxidative defence
A10: Macrobrachium rosenbergii | B10: MRO | C10: 0 | D10: 2 | E10: CAT_U_per_mg_protein | F10: 25.082 | G10: 24 | H10: 1 | I10: hepatopancreas | J10: oxidative defence
A11: Macrobrachium rosenbergii | B11: MRO | C11: 0 | D11: 3 | E11: CAT_U_per_mg_protein | F11: 24.551 | G11: 24 | H11: 1 | I11: hepatopancreas | J11: oxidative defence
A12: Macrobrachium rosenbergii | B12: MRO | C12: 0 | D12: 1 | E12: GST_nmol_per_min_mg | F12: 31.098 | G12: 32 | H12: 1 | I12: hepatopancreas | J12: phase II detoxification
A13: Macrobrachium rosenbergii | B13: MRO | C13: 0 | D13: 2 | E13: GST_nmol_per_min_mg | F13: 34.089 | G13: 32 | H13: 1 | I13: hepatopancreas | J13: phase II detoxification
A14: Macrobrachium rosenbergii | B14: MRO | C14: 0 | D14: 3 | E14: GST_nmol_per_min_mg | F14: 28.182 | G14: 32 | H14: 1 | I14: hepatopancreas | J14: phase II detoxification
A15: Macrobrachium rosenbergii | B15: MRO | C15: 0 | D15: 1 | E15: MDA_nmol_per_mg_protein | F15: 1.024 | G15: 1.2 | H15: 1 | I15: hepatopancreas | J15: lipid peroxidation, monotonic increase
A16: Macrobrachium rosenbergii | B16: MRO | C16: 0 | D16: 2 | E16: MDA_nmol_per_mg_protein | F16: 1.212 | G16: 1.2 | H16: 1 | I16: hepatopancreas | J16: lipid peroxidation, monotonic increase
A17: Macrobrachium rosenbergii | B17: MRO | C17: 0 | D17: 3 | E17: MDA_nmol_per_mg_protein | F17: 1.067 | G17: 1.2 | H17: 1 | I17: hepatopancreas | J17: lipid peroxidation, monotonic increase
... A185: Oreochromis niloticus | B185: ONI | C185: 20000 | D185: 3 | E185: AChE_nmol_per_min_mg | F185: 33.718 | G185: 46 | H185: 0.702 | I185: liver | J185: neurotoxicity, inhibition

Sheet 5b) Biomarker summary
A1: Biomarker means per dose
A2: mean of 3 analytical replicates
A3: Data status: synthetic (dummy) - generated, not measured
A5: species | B5: biomarker | C5: dose_pet_np_ug_L | D5: value | E5: fold_change_vs_control
A6: Macrobrachium rosenbergii | B6: AChE_nmol_per_min_mg | C6: 0 | D6: 44.065 | E6: 1
A7: Macrobrachium rosenbergii | B7: AChE_nmol_per_min_mg | C7: 50 | D7: 46.647 | E7: 0.95
A8: Macrobrachium rosenbergii | B8: AChE_nmol_per_min_mg | C8: 250 | D8: 41.151 | E8: 0.835
A9: Macrobrachium rosenbergii | B9: AChE_nmol_per_min_mg | C9: 1000 | D9: 32.108 | E9: 0.735
A10: Macrobrachium rosenbergii | B10: AChE_nmol_per_min_mg | C10: 5000 | D10: 29.87 | E10: 0.62
A11: Macrobrachium rosenbergii | B11: AChE_nmol_per_min_mg | C11: 20000 | D11: 24.22 | E11: 0.52
A12: Macrobrachium rosenbergii | B12: CAT_U_per_mg_protein | C12: 0 | D12: 25.477 | E12: 1
A13: Macrobrachium rosenbergii | B13: CAT_U_per_mg_protein | C13: 50 | D13: 27.581 | E13: 1.166
A14: Macrobrachium rosenbergii | B14: CAT_U_per_mg_protein | C14: 250 | D14: 35.499 | E14: 1.41
A15: Macrobrachium rosenbergii | B15: CAT_U_per_mg_protein | C15: 1000 | D15: 30.369 | E15: 1.348
A16: Macrobrachium rosenbergii | B16: CAT_U_per_mg_protein | C16: 5000 | D16: 23.823 | E16: 1.012
A17: Macrobrachium rosenbergii | B17: CAT_U_per_mg_protein | C17: 20000 | D17: 25.76 | E17: 1
... A65: Oreochromis niloticus | B65: SOD_U_per_mg_protein | C65: 20000 | D65: 17.849 | E65: 1

Sheet 6) Behaviour dynamics
A1: Behavioural dynamics, 0-96 h open-field tracking
A2: six traits x 6 doses x 7 time points x 3 replicates, both species
A5: species | B5: trait | C5: dose_pet_np_ug_L | D5: time_h | E5: mean_value | F5: sd_value
A6: Macrobrachium rosenbergii | B6: aggression_events_per_10min | C6: 0 | D6: 0 | E6: 1.935 | F6: 0.12
A7: Macrobrachium rosenbergii | B7: aggression_events_per_10min | C7: 0 | D7: 6 | E7: 1.901 | F7: 0.099
A8: Macrobrachium rosenbergii | B8: aggression_events_per_10min | C8: 0 | D8: 12 | E8: 1.825 | F8: 0.134
A9: Macrobrachium rosenbergii | B9: aggression_events_per_10min | C9: 0 | D9: 24 | E9: 1.984 | F9: 0.151
A10: Macrobrachium rosenbergii | B10: aggression_events_per_10min | C10: 0 | D10: 48 | E10: 1.783 | F10: 0.047
A11: Macrobrachium rosenbergii | B11: aggression_events_per_10min | C11: 0 | D11: 72 | E11: 1.986 | F11: 0.084
A12: Macrobrachium rosenbergii | B12: aggression_events_per_10min | C12: 0 | D12: 96 | E12: 1.845 | F12: 0.115
A13: Macrobrachium rosenbergii | B13: aggression_events_per_10min | C13: 50 | D13: 0 | E13: 1.981 | F13: 0.163
A14: Macrobrachium rosenbergii | B14: aggression_events_per_10min | C14: 50 | D14: 6 | E14: 1.952 | F14: 0.079
A15: Macrobrachium rosenbergii | B15: aggression_events_per_10min | C15: 50 | D15: 12 | E15: 1.873 | F15: 0.107
A16: Macrobrachium rosenbergii | B16: aggression_events_per_10min | C16: 50 | D16: 24 | E16: 1.836 | F16: 0.107
A17: Macrobrachium rosenbergii | B17: aggression_events_per_10min | C17: 50 | D17: 48 | E17: 1.855 | F17: 0.129
... A509: Oreochromis niloticus | B509: thigmotaxis_pct_time_wall_zone | C509: 20000 | D509: 96 | E509: 47.184 | F509: 0.873
A511: Thigmotaxis (% time in wall zone), Macrobrachium - dose x time
A512: time_h | B512: 0 µg/L | C512: 50 µg/L | D512: 250 µg/L | E512: 1,000 µg/L | F512: 5,000 µg/L | G512: 20,000 µg/L
A513: 0 | B513: 30.202 | C513: 34.397 | D513: 33.102 | E513: 32.005 | F513: 31.98 | G513: 33.562
A514: 6 | B514: 31.538 | C514: 32.081 | D514: 32.272 | E514: 33.344 | F514: 36.543 | G514: 38.18
A515: 12 | B515: 34.181 | C515: 32.081 | D515: 35.628 | E515: 37.185 | F515: 39.543 | G515: 43.028
A516: 24 | B516: 31.424 | C516: 33.652 | D516: 37.144 | E516: 38.756 | F516: 41.356 | G516: 48.78
A517: 48 | B517: 31.831 | C517: 33.118 | D517: 40.061 | E517: 45.129 | F517: 53.162 | G517: 54.587
A518: 72 | B518: 33.774 | C518: 36.355 | D518: 41.522 | E518: 45.854 | F518: 54.78 | G518: 60.295
A519: 96 | B519: 33.114 | C519: 34.11 | D519: 42.88 | E519: 49.61 | F519: 55.381 | G519: 61.647

Sheet 7) Bioaccumulation
A1: Tissue burden and bioconcentration factors
A2: 96 h exposure, 48 h depuration removal reported per tissue
A3: Data status: synthetic (dummy) - generated, not measured
A5: species | B5: species_code | C5: tissue | D5: dose_pet_np_ug_L | E5: replicate | F5: exposure_h | G5: tissue_conc_ug_per_g_ww | H5: bcf_L_per_kg | I5: depuration_48h_removal_pct
A6: Macrobrachium rosenbergii | B6: MRO | C6: gill | D6: 50 | E6: 1 | F6: 96 | G6: 0.6297 | H6: 12.59 | I6: 35.5
A7: Macrobrachium rosenbergii | B7: MRO | C7: gill | D7: 50 | E7: 2 | F7: 96 | G7: 0.7797 | H7: 15.59 | I7: 32.5
A8: Macrobrachium rosenbergii | B8: MRO | C8: gill | D8: 50 | E8: 3 | F8: 96 | G8: 0.6366 | H8: 12.73 | I8: 27.3
A9: Macrobrachium rosenbergii | B9: MRO | C9: hepatopancreas | D9: 50 | E9: 1 | F9: 96 | G9: 0.5268 | H9: 10.54 | I9: 25.4
A10: Macrobrachium rosenbergii | B10: MRO | C10: hepatopancreas | D10: 50 | E10: 2 | F10: 96 | G10: 0.5152 | H10: 10.3 | I10: 33.4
A11: Macrobrachium rosenbergii | B11: MRO | C11: hepatopancreas | D11: 50 | E11: 3 | F11: 96 | G11: 0.5091 | H11: 10.18 | I11: 21
A12: Macrobrachium rosenbergii | B12: MRO | C12: gut | D12: 50 | E12: 1 | F12: 96 | G12: 0.88 | H12: 17.6 | I12: 59.9
A13: Macrobrachium rosenbergii | B13: MRO | C13: gut | D13: 50 | E13: 2 | F13: 96 | G13: 1.0315 | H13: 20.63 | I13: 68.2
A14: Macrobrachium rosenbergii | B14: MRO | C14: gut | D14: 50 | E14: 3 | F14: 96 | G14: 0.8412 | H14: 16.82 | I14: 65.8
A15: Macrobrachium rosenbergii | B15: MRO | C15: muscle | D15: 50 | E15: 1 | F15: 96 | G15: 0.0846 | H15: 1.69 | I15: 30.1
A16: Macrobrachium rosenbergii | B16: MRO | C16: muscle | D16: 50 | E16: 2 | F16: 96 | G16: 0.0692 | H16: 1.38 | I16: 33.3
A17: Macrobrachium rosenbergii | B17: MRO | C17: muscle | D17: 50 | E17: 3 | F17: 96 | G17: 0.0667 | H17: 1.33 | I17: 38.7
... A125: Oreochromis niloticus | B125: ONI | C125: muscle | D125: 20000 | E125: 3 | F125: 96 | G125: 12.1012 | H125: 0.61 | I125: 28.3

Sheet 8) SSD & HC5
A1: Species sensitivity distribution and PNEC
A2: log-normal SSD over 12 taxa; HC5 confidence interval from 2000 bootstrap resamples
A3: Data status: synthetic (dummy) - generated, not measured
A5: species | B5: taxonomic_group | C5: endpoint | D5: noec_or_ec10_ug_L | E5: source_status | F5: rank | G5: cumulative_probability | H5: log10_conc
A6: Daphnia magna | B6: cladoceran | C6: reproduction NOEC | D6: 95 | E6: literature-anchored range | F6: 1 | G6: 0.0417 | H6: 1.9777
A7: Ceriodaphnia dubia | B7: cladoceran | C7: reproduction NOEC | D7: 130 | E7: dummy | F7: 2 | G7: 0.125 | H7: 2.1139
A8: Macrobrachium rosenbergii | B8: decapod crustacean | C8: growth EC10 (this study) | D8: 165 | E8: dummy - this study | F8: 3 | G8: 0.2083 | H8: 2.2175
A9: Moina macrocopa | B9: cladoceran | C9: survival NOEC | D9: 220 | E9: dummy | F9: 4 | G9: 0.2917 | H9: 2.3424
A10: Chlorella vulgaris | B10: green algae | C10: growth rate EC10 | D10: 320 | E10: literature-anchored range | F10: 5 | G10: 0.375 | H10: 2.5051
A11: Corbicula fluminea | B11: bivalve | C11: filtration EC10 | D11: 380 | E11: dummy | F11: 6 | G11: 0.4583 | H11: 2.5798
A12: Scenedesmus obliquus | B12: green algae | C12: growth rate EC10 | D12: 410 | E12: literature-anchored range | F12: 7 | G12: 0.5417 | H12: 2.6128
A13: Brachionus plicatilis | B13: rotifer | C13: population growth EC10 | D13: 480 | E13: dummy | F13: 8 | G13: 0.625 | H13: 2.6812
A14: Danio rerio | B14: fish | C14: behaviour EC10 | D14: 540 | E14: literature-anchored range | F14: 9 | G14: 0.7083 | H14: 2.7324
A15: Oreochromis niloticus | B15: fish | C15: growth EC10 (this study) | D15: 640 | E15: dummy - this study | F15: 10 | G15: 0.7917 | H15: 2.8062
A16: Chironomus riparius | B16: insect larva | C16: emergence NOEC | D16: 760 | E16: dummy | F16: 11 | G16: 0.875 | H16: 2.8808
A17: Lemna minor | B17: macrophyte | C17: frond number EC10 | D17: 1250 | E17: dummy | F17: 12 | G17: 0.9583 | H17: 3.0969
A20: mu of log10(NOEC) | B20: =AVERAGE(H6:H17) -> 2.5455583
A21: sigma of log10(NOEC) | B21: =STDEV(H6:H17) -> 0.33065026
A22: HC50 (µg/L) | B22: =10^B20 -> 351.20309
A23: HC5 (µg/L) | B23: =10^(B20+_xludf.NORM.S.INV(0.05)*B21) -> #NAME?
A24: Assessment factor (editable) | B24: 3
A25: PNEC (µg/L) | B25: =B23/B24 -> #NAME?
A26: HC5 95 % CI low (bootstrap, µg/L) | B26: 60.32
A27: HC5 95 % CI high (bootstrap, µg/L) | B27: 221.76

Sheet 9) Risk (PEC-PNEC)
A1: Risk characterisation per station and season
A2: PEC from sheet 3, PNEC linked from sheet 8; RQ and class are live formulas
A3: Data status: synthetic (dummy) - generated, not measured
A5: station_code | B5: station_name | C5: regency | D5: river_km | E5: season | F5: pec_mean_ug_L | G5: pec_max_ug_L | H5: pec_sd_ug_L | I5: pec_95th_ug_L | J5: hc5_ug_L | K5: assessment_factor | L5: pnec_ug_L | M5: rq_mean | N5: rq_reasonable_worst_case | O5: risk_class_mean | P5: risk_class_rwc
A6: ST1 | B6: Situ Cisanti (headwater) | C6: Kab. Bandung | D6: 0 | E6: Hujan (wet, Dec-Feb) | F6: 1.34 | G6: 1.63 | H6: 0.26 | I6: 1.76 | J6: ='8) SSD & HC5'!$B$23 -> #NAME? | K6: 3 | L6: =J6/K6 -> #NAME? | M6: =F6/L6 -> #NAME? | N6: =I6/L6 -> #NAME? | O6: =IF(M6<0.1,"negligible",IF(M6<1,"low",IF(M6<10,"moderate","high"))) -> #NAME? | P6: =IF(N6<0.1,"negligible",IF(N6<1,"low",IF(N6<10,"moderate","high"))) -> #NAME?
A7: ST1 | B7: Situ Cisanti (headwater) | C7: Kab. Bandung | D7: 0 | E7: Kemarau (dry, Jul-Sep) | F7: 0.89 | G7: 0.93 | H7: 0.05 | I7: 0.98 | J7: ='8) SSD & HC5'!$B$23 -> #NAME? | K7: 3 | L7: =J7/K7 -> #NAME? | M7: =F7/L7 -> #NAME? | N7: =I7/L7 -> #NAME? | O7: =IF(M7<0.1,"negligible",IF(M7<1,"low",IF(M7<10,"moderate","high"))) -> #NAME? | P7: =IF(N7<0.1,"negligible",IF(N7<1,"low",IF(N7<10,"moderate","high"))) -> #NAME?
A8: ST1 | B8: Situ Cisanti (headwater) | C8: Kab. Bandung | D8: 0 | E8: Transisi (Apr-Jun/Oct) | F8: 0.98 | G8: 1.23 | H8: 0.23 | I8: 1.35 | J8: ='8) SSD & HC5'!$B$23 -> #NAME? | K8: 3 | L8: =J8/K8 -> #NAME? | M8: =F8/L8 -> #NAME? | N8: =I8/L8 -> #NAME? | O8: =IF(M8<0.1,"negligible",IF(M8<1,"low",IF(M8<10,"moderate","high"))) -> #NAME? | P8: =IF(N8<0.1,"negligible",IF(N8<1,"low",IF(N8<10,"moderate","high"))) -> #NAME?
A9: ST2 | B9: Majalaya (textile cluster) | C9: Kab. Bandung | D9: 32 | E9: Hujan (wet, Dec-Feb) | F9: 46.35 | G9: 53.9 | H9: 6.62 | I9: 57.23 | J9: ='8) SSD & HC5'!$B$23 -> #NAME? | K9: 3 | L9: =J9/K9 -> #NAME? | M9: =F9/L9 -> #NAME? | N9: =I9/L9 -> #NAME? | O9: =IF(M9<0.1,"negligible",IF(M9<1,"low",IF(M9<10,"moderate","high"))) -> #NAME? | P9: =IF(N9<0.1,"negligible",IF(N9<1,"low",IF(N9<10,"moderate","high"))) -> #NAME?
A10: ST2 | B10: Majalaya (textile cluster) | C10: Kab. Bandung | D10: 32 | E10: Kemarau (dry, Jul-Sep) | F10: 25.11 | G10: 26.43 | H10: 1.17 | I10: 27.04 | J10: ='8) SSD & HC5'!$B$23 -> #NAME? | K10: 3 | L10: =J10/K10 -> #NAME? | M10: =F10/L10 -> #NAME? | N10: =I10/L10 -> #NAME? | O10: =IF(M10<0.1,"negligible",IF(M10<1,"low",IF(M10<10,"moderate","high"))) -> #NAME? | P10: =IF(N10<0.1,"negligible",IF(N10<1,"low",IF(N10<10,"moderate","high"))) -> #NAME?
A11: ST2 | B11: Majalaya (textile cluster) | C11: Kab. Bandung | D11: 32 | E11: Transisi (Apr-Jun/Oct) | F11: 38.1 | G11: 47.56 | H11: 8.31 | I11: 51.77 | J11: ='8) SSD & HC5'!$B$23 -> #NAME? | K11: 3 | L11: =J11/K11 -> #NAME? | M11: =F11/L11 -> #NAME? | N11: =I11/L11 -> #NAME? | O11: =IF(M11<0.1,"negligible",IF(M11<1,"low",IF(M11<10,"moderate","high"))) -> #NAME? | P11: =IF(N11<0.1,"negligible",IF(N11<1,"low",IF(N11<10,"moderate","high"))) -> #NAME?
A12: ST3 | B12: Dayeuhkolot | C12: Kab. Bandung | D12: 54 | E12: Hujan (wet, Dec-Feb) | F12: 60.61 | G12: 67.84 | H12: 6.56 | I12: 71.4 | J12: ='8) SSD & HC5'!$B$23 -> #NAME? | K12: 3 | L12: =J12/K12 -> #NAME? | M12: =F12/L12 -> #NAME? | N12: =I12/L12 -> #NAME? | O12: =IF(M12<0.1,"negligible",IF(M12<1,"low",IF(M12<10,"moderate","high"))) -> #NAME? | P12: =IF(N12<0.1,"negligible",IF(N12<1,"low",IF(N12<10,"moderate","high"))) -> #NAME?
A13: ST3 | B13: Dayeuhkolot | C13: Kab. Bandung | D13: 54 | E13: Kemarau (dry, Jul-Sep) | F13: 41.01 | G13: 48.65 | H13: 7.71 | I13: 53.69 | J13: ='8) SSD & HC5'!$B$23 -> #NAME? | K13: 3 | L13: =J13/K13 -> #NAME? | M13: =F13/L13 -> #NAME? | N13: =I13/L13 -> #NAME? | O13: =IF(M13<0.1,"negligible",IF(M13<1,"low",IF(M13<10,"moderate","high"))) -> #NAME? | P13: =IF(N13<0.1,"negligible",IF(N13<1,"low",IF(N13<10,"moderate","high"))) -> #NAME?
A14: ST3 | B14: Dayeuhkolot | C14: Kab. Bandung | D14: 54 | E14: Transisi (Apr-Jun/Oct) | F14: 50.43 | G14: 54.85 | H14: 6.76 | I14: 61.54 | J14: ='8) SSD & HC5'!$B$23 -> #NAME? | K14: 3 | L14: =J14/K14 -> #NAME? | M14: =F14/L14 -> #NAME? | N14: =I14/L14 -> #NAME? | O14: =IF(M14<0.1,"negligible",IF(M14<1,"low",IF(M14<10,"moderate","high"))) -> #NAME? | P14: =IF(N14<0.1,"negligible",IF(N14<1,"low",IF(N14<10,"moderate","high"))) -> #NAME?
A15: ST4 | B15: Nanjung - Bandung Barat | C15: Kab. Bandung Barat | D15: 71 | E15: Hujan (wet, Dec-Feb) | F15: 42.51 | G15: 47.44 | H15: 4.92 | I15: 50.6 | J15: ='8) SSD & HC5'!$B$23 -> #NAME? | K15: 3 | L15: =J15/K15 -> #NAME? | M15: =F15/L15 -> #NAME? | N15: =I15/L15 -> #NAME? | O15: =IF(M15<0.1,"negligible",IF(M15<1,"low",IF(M15<10,"moderate","high"))) -> #NAME? | P15: =IF(N15<0.1,"negligible",IF(N15<1,"low",IF(N15<10,"moderate","high"))) -> #NAME?
A16: ST4 | B16: Nanjung - Bandung Barat | C16: Kab. Bandung Barat | D16: 71 | E16: Kemarau (dry, Jul-Sep) | F16: 20.43 | G16: 22.62 | H16: 2.11 | I16: 23.9 | J16: ='8) SSD & HC5'!$B$23 -> #NAME? | K16: 3 | L16: =J16/K16 -> #NAME? | M16: =F16/L16 -> #NAME? | N16: =I16/L16 -> #NAME? | O16: =IF(M16<0.1,"negligible",IF(M16<1,"low",IF(M16<10,"moderate","high"))) -> #NAME? | P16: =IF(N16<0.1,"negligible",IF(N16<1,"low",IF(N16<10,"moderate","high"))) -> #NAME?
A17: ST4 | B17: Nanjung - Bandung Barat | C17: Kab. Bandung Barat | D17: 71 | E17: Transisi (Apr-Jun/Oct) | F17: 26.49 | G17: 28.42 | H17: 2.39 | I17: 30.42 | J17: ='8) SSD & HC5'!$B$23 -> #NAME? | K17: 3 | L17: =J17/K17 -> #NAME? | M17: =F17/L17 -> #NAME? | N17: =I17/L17 -> #NAME? | O17: =IF(M17<0.1,"negligible",IF(M17<1,"low",IF(M17<10,"moderate","high"))) -> #NAME? | P17: =IF(N17<0.1,"negligible",IF(N17<1,"low",IF(N17<10,"moderate","high"))) -> #NAME?
... A29: ST8 | B29: Muara Gembong (estuary) | C29: Kab. Bekasi | D29: 269 | E29: Transisi (Apr-Jun/Oct) | F29: 26.01 | G29: 29.32 | H29: 2.91 | I29: 30.79 | J29: ='8) SSD & HC5'!$B$23 -> #NAME? | K29: 3 | L29: =J29/K29 -> #NAME? | M29: =F29/L29 -> #NAME? | N29: =I29/L29 -> #NAME? | O29: =IF(M29<0.1,"negligible",IF(M29<1,"low",IF(M29<10,"moderate","high"))) -> #NAME? | P29: =IF(N29<0.1,"negligible",IF(N29<1,"low",IF(N29<10,"moderate","high"))) -> #NAME?

Sheet 10) EIA Leopold matrix
A1: Leopold interaction matrix
A2: magnitude (-5..+5) x importance (1..5); only interacting cells are listed
A3: Data status: synthetic (dummy) - generated, not measured
A5: activity | B5: component_category | C5: environmental_component | D5: magnitude_minus5_to_plus5 | E5: importance_1_to_5 | F5: interaction_score | G5: direction
A6: PET resin production & preform moulding (Bekasi-Karawang industrial belt) | B6: Physico-chemical | C6: Surface water quality (PET NP, TSS, DOC) | D6: -3 | E6: 3 | F6: =D6*E6 -> -9 | G6: =IF(D6<0,"adverse","beneficial") -> adverse
A7: PET resin production & preform moulding (Bekasi-Karawang industrial belt) | B7: Physico-chemical | C7: Sediment quality | D7: -2 | E7: 3 | F7: =D7*E7 -> -6 | G7: =IF(D7<0,"adverse","beneficial") -> adverse
A8: PET resin production & preform moulding (Bekasi-Karawang industrial belt) | B8: Physico-chemical | C8: Air quality (combustion by-products) | D8: -2 | E8: 3 | F8: =D8*E8 -> -6 | G8: =IF(D8<0,"adverse","beneficial") -> adverse
A9: PET resin production & preform moulding (Bekasi-Karawang industrial belt) | B9: Biological | C9: Small crustaceans (Macrobrachium) | D9: -2 | E9: 3 | F9: =D9*E9 -> -6 | G9: =IF(D9<0,"adverse","beneficial") -> adverse
A10: PET resin production & preform moulding (Bekasi-Karawang industrial belt) | B10: Biological | C10: Fish community & aquaculture stock (Oreochromis) | D10: -2 | E10: 3 | F10: =D10*E10 -> -6 | G10: =IF(D10<0,"adverse","beneficial") -> adverse
A11: PET resin production & preform moulding (Bekasi-Karawang industrial belt) | B11: Biological | C11: Benthic macroinvertebrates | D11: -1 | E11: 2 | F11: =D11*E11 -> -2 | G11: =IF(D11<0,"adverse","beneficial") -> adverse
A12: PET resin production & preform moulding (Bekasi-Karawang industrial belt) | B12: Socio-economic | C12: Fisher & fish-farmer livelihood | D12: -1 | E12: 2 | F12: =D12*E12 -> -2 | G12: =IF(D12<0,"adverse","beneficial") -> adverse
A13: PET resin production & preform moulding (Bekasi-Karawang industrial belt) | B13: Socio-economic | C13: Drinking water supply & public health | D13: -1 | E13: 3 | F13: =D13*E13 -> -3 | G13: =IF(D13<0,"adverse","beneficial") -> adverse
A14: PET resin production & preform moulding (Bekasi-Karawang industrial belt) | B14: Socio-economic | C14: Informal waste-picker occupational exposure | D14: -1 | E14: 2 | F14: =D14*E14 -> -2 | G14: =IF(D14<0,"adverse","beneficial") -> adverse
A15: Bottling, filling and distribution | B15: Physico-chemical | C15: Surface water quality (PET NP, TSS, DOC) | D15: -2 | E15: 2 | F15: =D15*E15 -> -4 | G15: =IF(D15<0,"adverse","beneficial") -> adverse
A16: Bottling, filling and distribution | B16: Physico-chemical | C16: Sediment quality | D16: -1 | E16: 2 | F16: =D16*E16 -> -2 | G16: =IF(D16<0,"adverse","beneficial") -> adverse
A17: Bottling, filling and distribution | B17: Physico-chemical | C17: Air quality (combustion by-products) | D17: -1 | E17: 2 | F17: =D17*E17 -> -2 | G17: =IF(D17<0,"adverse","beneficial") -> adverse
... A69: Raw water abstraction & drinking water treatment (Jatiluhur) | B69: Socio-economic | C69: Drinking water supply & public health | D69: 3 | E69: 5 | F69: =D69*E69 -> 15 | G69: =IF(D69<0,"adverse","beneficial") -> beneficial
A71: Sum of adverse interaction scores | F71: =SUMIF(F6:F69,"<0") -> -571

Sheet 11) EIA RIAM scoring
A1: Rapid Impact Assessment Matrix (RIAM)
A2: ES = (A1 x A2) x (B1 + B2 + B3); range classes follow Pastakia & Jensen (1998)
A3: Data status: synthetic (dummy) - generated, not measured
A5: environmental_component | B5: A1_importance_of_condition | C5: A2_magnitude_of_change | D5: B1_permanence | E5: B2_reversibility | F5: B3_cumulative | G5: AT_A1xA2 | H5: BT_B1plusB2plusB3 | I5: ES_environmental_score | J5: riam_range_class | K5: significance | L5: mitigation_measure | M5: data_status
A6: Surface water quality (PET NP) | B6: 4 | C6: -3 | D6: 3 | E6: 2 | F6: 3 | G6: =B6*C6 -> -12 | H6: =D6+E6+F6 -> 8 | I6: =G6*H6 -> -96 | J6: -E | K6: major negative | L6: Interception booms + Majalaya WWTP nano-filtration retrofit; EPR on PET bottles | M6: synthetic (dummy) - generated, not measured
A7: Small crustaceans (Macrobrachium) | B7: 3 | C7: -3 | D7: 2 | E7: 2 | F7: 3 | G7: =B7*C7 -> -9 | H7: =D7+E7+F7 -> 7 | I7: =G7*H7 -> -63 | J7: -D | K7: significant negative | L7: Seasonal restocking ban during wet-season peaks; hatchery water screening | M7: synthetic (dummy) - generated, not measured
A8: Fish community & aquaculture stock | B8: 4 | C8: -2 | D8: 2 | E8: 2 | F8: 3 | G8: =B8*C8 -> -8 | H8: =D8+E8+F8 -> 7 | I8: =G8*H8 -> -56 | J8: -D | K8: significant negative | L8: Cage siting away from tributary inflows; feed & tissue surveillance | M8: synthetic (dummy) - generated, not measured
A9: Drinking water supply & public health | B9: 4 | C9: -2 | D9: 2 | E9: 2 | F9: 3 | G9: =B9*C9 -> -8 | H9: =D9+E9+F9 -> 7 | I9: =G9*H9 -> -56 | J9: -D | K9: significant negative | L9: Nano-filtration step + PET NP in raw-water monitoring protocol | M9: synthetic (dummy) - generated, not measured
A10: Sediment quality | B10: 3 | C10: -2 | D10: 3 | E10: 3 | F10: 3 | G10: =B10*C10 -> -6 | H10: =D10+E10+F10 -> 9 | I10: =G10*H10 -> -54 | J10: -D | K10: significant negative | L10: Sediment monitoring at Saguling/Cirata; dredging spoil management | M10: synthetic (dummy) - generated, not measured
A11: Air quality (open burning) | B11: 3 | C11: -3 | D11: 1 | E11: 2 | F11: 2 | G11: =B11*C11 -> -9 | H11: =D11+E11+F11 -> 5 | I11: =G11*H11 -> -45 | J11: -D | K11: significant negative | L11: Close open dumps; formalise collection in Kab. Bandung | M11: synthetic (dummy) - generated, not measured
A12: Fisher & fish-farmer livelihood | B12: 3 | C12: -2 | D12: 2 | E12: 2 | F12: 2 | G12: =B12*C12 -> -6 | H12: =D12+E12+F12 -> 6 | I12: =G12*H12 -> -36 | J12: -D | K12: significant negative | L12: Alternative livelihood + compensation scheme | M12: synthetic (dummy) - generated, not measured
A13: Waste-picker occupational exposure | B13: 2 | C13: -3 | D13: 2 | E13: 2 | F13: 2 | G13: =B13*C13 -> -6 | H13: =D13+E13+F13 -> 6 | I13: =G13*H13 -> -36 | J13: -D | K13: significant negative | L13: PPE, formal cooperatives, health screening | M13: synthetic (dummy) - generated, not measured
A14: Benthic macroinvertebrates | B14: 2 | C14: -2 | D14: 2 | E14: 2 | F14: 2 | G14: =B14*C14 -> -4 | H14: =D14+E14+F14 -> 6 | I14: =G14*H14 -> -24 | J14: -C | K14: moderate negative | L14: Habitat protection in upstream reaches | M14: synthetic (dummy) - generated, not measured
A15: Reservoir operation (Cirata) | B15: 2 | C15: -1 | D15: 2 | E15: 3 | F15: 2 | G15: =B15*C15 -> -2 | H15: =D15+E15+F15 -> 7 | I15: =G15*H15 -> -14 | J15: -B | K15: negative | L15: Trash rack maintenance, drawdown-timed clean-ups | M15: synthetic (dummy) - generated, not measured
A16: Recycling sector value creation | B16: 3 | C16: 2 | D16: 2 | E16: 3 | F16: 2 | G16: =B16*C16 -> 6 | H16: =D16+E16+F16 -> 7 | I16: =G16*H16 -> 42 | J16: D | K16: significant positive | L16: Support bottle-to-bottle recycling capacity | M16: synthetic (dummy) - generated, not measured

Sheet 12) LCA inventory
A1: Screening LCI - 1 kg PET bottle-grade resin, cradle-to-grave
A2: proxy characterisation factors; replace with a licensed ecoinvent 3.10 dataset
A3: Data status: synthetic (dummy) - generated, not measured
A5: life_cycle_stage | B5: flow | C5: amount | D5: unit | E5: gwp100_kgCO2e | F5: ced_MJ | G5: water_consumption_m3 | H5: note | I5: functional_unit
A6: A1 Raw material supply | B6: Crude oil / naphtha input | C6: 1.42 | D6: kg | E6: 0.52 | F6: 24 | G6: 0.0021 | H6: upstream extraction & refining | I6: 1 kg PET bottle-grade resin, cradle-to-grave
A7: A1 Raw material supply | B7: Purified terephthalic acid (PTA) | C7: 0.86 | D7: kg | E7: 1.21 | F7: 21.5 | G7: 0.0104 | H7: proxy factor | I7: 1 kg PET bottle-grade resin, cradle-to-grave
A8: A1 Raw material supply | B8: Monoethylene glycol (MEG) | C8: 0.34 | D8: kg | E8: 0.58 | F8: 9.8 | G8: 0.0061 | H8: proxy factor | I8: 1 kg PET bottle-grade resin, cradle-to-grave
A9: A2 Transport to converter | B9: Road freight, 18 t truck | C9: 0.42 | D9: t.km | E9: 0.05 | F9: 0.7 | G9: 0.0002 | H9: Cilegon-Bekasi average | I9: 1 kg PET bottle-grade resin, cradle-to-grave
A10: A3 Polymerisation & resin | B10: Electricity, Jamali grid | C10: 1.05 | D10: kWh | E10: 0.83 | F10: 8.6 | G10: 0.0038 | H10: 0.79 kg CO2e/kWh grid factor | I10: 1 kg PET bottle-grade resin, cradle-to-grave
A11: A3 Polymerisation & resin | B11: Natural gas, process heat | C11: 6.2 | D11: MJ | E11: 0.39 | F11: 6.8 | G11: 0.0004 | H11: steam and drying | I11: 1 kg PET bottle-grade resin, cradle-to-grave
A12: A4 Preform & bottle moulding | B12: Electricity, Jamali grid | C12: 0.62 | D12: kWh | E12: 0.49 | F12: 5.1 | G12: 0.0022 | H12: injection + stretch blow | I12: 1 kg PET bottle-grade resin, cradle-to-grave
A13: A5 Filling & distribution | B13: Road freight, distribution | C13: 0.85 | D13: t.km | E13: 0.1 | F13: 1.4 | G13: 0.0004 | H13: regional distribution | I13: 1 kg PET bottle-grade resin, cradle-to-grave
A14: B1 Use phase | B14: Refrigeration & retail (allocated) | C14: 0.18 | D14: kWh | E14: 0.14 | F14: 1.5 | G14: 0.0006 | H14: allocated share | I14: 1 kg PET bottle-grade resin, cradle-to-grave
A15: C1 Collection & sorting | B15: Diesel, collection fleet | C15: 0.031 | D15: kg | E15: 0.1 | F15: 1.4 | G15: 0.0001 | H15: 62 % collection rate assumed | I15: 1 kg PET bottle-grade resin, cradle-to-grave
A16: C2 Mechanical recycling | B16: Electricity + washing water | C16: 0.28 | D16: kWh | E16: 0.22 | F16: 2.3 | G16: 0.018 | H16: applies to recycled fraction | I16: 1 kg PET bottle-grade resin, cradle-to-grave
A17: C3 Landfill / open dump | B17: PET to landfill or open dump | C17: 0.3 | D17: kg | E17: 0.02 | F17: 0.1 | G17: 0 | H17: inert, slow fragmentation | I17: 1 kg PET bottle-grade resin, cradle-to-grave
... A19: C5 Leakage to river | B19: PET debris to Citarum | C19: 0.045 | D19: kg | E19: 0 | F19: 0 | G19: 0 | H19: source term for nanoplastic release | I19: 1 kg PET bottle-grade resin, cradle-to-grave
A21: Total cradle-to-grave (before EOL scenario) | E21: =SUM(E6:E19) -> 4.84

Sheet 13) LCA impacts & EOL
A1: Impact results by stage and end-of-life scenario
A2: shares are live formulas; nanoplastic release links climate results to the exposure module
A3: Data status: synthetic (dummy) - generated, not measured
A5: life_cycle_stage | B5: gwp100_kgCO2e | C5: ced_MJ | D5: water_consumption_m3 | E5: share_of_gwp_pct
A6: A1 Raw material supply | B6: 2.31 | C6: 55.3 | D6: 0.0186 | E6: =100*B6/SUM(B$6:B$16) -> 47.727273
A7: A2 Transport to converter | B7: 0.05 | C7: 0.7 | D7: 0.0002 | E7: =100*B7/SUM(B$6:B$16) -> 1.0330579
A8: A3 Polymerisation & resin | B8: 1.22 | C8: 15.4 | D8: 0.0042 | E8: =100*B8/SUM(B$6:B$16) -> 25.206612
A9: A4 Preform & bottle moulding | B9: 0.49 | C9: 5.1 | D9: 0.0022 | E9: =100*B9/SUM(B$6:B$16) -> 10.123967
A10: A5 Filling & distribution | B10: 0.1 | C10: 1.4 | D10: 0.0004 | E10: =100*B10/SUM(B$6:B$16) -> 2.0661157
A11: B1 Use phase | B11: 0.14 | C11: 1.5 | D11: 0.0006 | E11: =100*B11/SUM(B$6:B$16) -> 2.892562
A12: C1 Collection & sorting | B12: 0.1 | C12: 1.4 | D12: 0.0001 | E12: =100*B12/SUM(B$6:B$16) -> 2.0661157
A13: C2 Mechanical recycling | B13: 0.22 | C13: 2.3 | D13: 0.018 | E13: =100*B13/SUM(B$6:B$16) -> 4.5454545
A14: C3 Landfill / open dump | B14: 0.02 | C14: 0.1 | D14: 0 | E14: =100*B14/SUM(B$6:B$16) -> 0.41322314
A15: C4 Open burning | B15: 0.19 | C15: 0 | D15: 0 | E15: =100*B15/SUM(B$6:B$16) -> 3.9256198
A16: C5 Leakage to river | B16: 0 | C16: 0 | D16: 0 | E16: =100*B16/SUM(B$6:B$16) -> 0
A35: End-of-life scenarios
A36: eol_scenario | B36: recycling_frac | C36: landfill_frac | D36: open_burning_frac | E36: river_leakage_frac | F36: gwp100_kgCO2e_per_kg | G36: recycling_credit_kgCO2e | H36: open_burning_kgCO2e | I36: pet_to_river_g_per_kg | J36: np_release_factor_mg_per_kg_leaked | K36: pet_np_release_mg_per_kg_resin | L36: description | M36: functional_unit | N36: data_status
A37: S0 Business as usual (2024 baseline) | B37: 0.13 | C37: 0.66 | D37: 0.16 | E37: 0.05 | F37: 4.805 | G37: -0.241 | H37: 0.376 | I37: =E37*1000 -> 50 | J37: 920 | K37: =E37*J37 -> 46 | L37: current Jawa Barat collection and treatment mix | M37: 1 kg PET bottle-grade resin, cradle-to-grave | N37: synthetic (dummy) - generated, not measured
A38: S1 Improved collection (Citarum Harum target) | B38: 0.22 | C38: 0.68 | D38: 0.08 | E38: 0.02 | F38: 4.452 | G38: -0.407 | H38: 0.188 | I38: =E38*1000 -> 20 | J38: 380 | K38: =E38*J38 -> 7.6 | L38: collection to 80 %, open burning halved | M38: 1 kg PET bottle-grade resin, cradle-to-grave | N38: synthetic (dummy) - generated, not measured
A39: S2 EPR + bottle-to-bottle recycling | B39: 0.45 | C39: 0.5 | D39: 0.04 | E39: 0.01 | F39: 3.921 | G39: -0.833 | H39: 0.094 | I39: =E39*1000 -> 10 | J39: 190 | K39: =E39*J39 -> 1.9 | L39: deposit-return, formalised waste pickers | M39: 1 kg PET bottle-grade resin, cradle-to-grave | N39: synthetic (dummy) - generated, not measured
A40: S3 Full containment (upper bound) | B40: 0.6 | C40: 0.38 | D40: 0.01 | E40: 0.002 | F40: 3.566 | G40: -1.11 | H40: 0.024 | I40: =E40*1000 -> 2 | J40: 40 | K40: =E40*J40 -> 0.08 | L40: aspirational, near-zero leakage | M40: 1 kg PET bottle-grade resin, cradle-to-grave | N40: synthetic (dummy) - generated, not measured

Sheet 14) Integrated scorecard
A1: Integrated scorecard per station
A2: weighted combination of ecotoxicity, risk, EIA significance and exposure; weights are editable
A3: Data status: synthetic (dummy) - generated, not measured
A5: w_ecotox | B5: 0.3 | C5: w_risk | D5: 0.35 | E5: w_eia | F5: 0.2 | G5: w_exposure | H5: 0.15
A6: weights must sum to 1 -> | B6: =$B$5+$D$5+$F$5+$H$5 -> 1
A7: station_code | B7: station_name | C7: regency | D7: river_km | E7: pressure_type | F7: pec_mean_ug_L | G7: pec_wet_ug_L | H7: pec_transition_ug_L | I7: rq_mean_all_seasons | J7: rq_worst_case | K7: toxic_unit_most_sensitive_endpoint | L7: eia_pressure_weight | M7: eia_weighted_negative_ES | N7: ecotox_index_0_100 | O7: risk_index_0_100 | P7: eia_index_0_100 | Q7: exposure_index_0_100 | R7: w_ecotox | S7: w_risk | T7: w_eia | U7: w_exposure | V7: integrated_index_0_100 | W7: priority_class
A8: ST1 | B8: Situ Cisanti (headwater) | C8: Kab. Bandung | D8: 0 | E8: reference / upstream forest | F8: 1.07 | G8: 1.34 | H8: 0.98 | I8: 0.032 | J8: 0.053 | K8: 0.0021 | L8: 0.2 | M8: 96 | N8: 0 | O8: 0 | P8: 0 | Q8: 0 | R8: 0.3 | S8: 0.35 | T8: 0.2 | U8: 0.15 | V8: =$B$5*N8+$D$5*O8+$F$5*P8+$H$5*Q8 -> 0 | W8: =IF(V8<25,"low",IF(V8<50,"moderate",IF(V8<75,"high","very high"))) -> low
A9: ST2 | B9: Majalaya (textile cluster) | C9: Kab. Bandung | D9: 32 | E9: textile wastewater | F9: 36.52 | G9: 46.35 | H9: 38.1 | I9: 1.0913333 | J9: 1.71 | K9: 0.0736 | L9: 1 | M9: 480 | N9: 93 | O9: 94 | P9: 100 | Q9: 91.5 | R9: 0.3 | S9: 0.35 | T9: 0.2 | U9: 0.15 | V9: =$B$5*N9+$D$5*O9+$F$5*P9+$H$5*Q9 -> 94.525 | W9: =IF(V9<25,"low",IF(V9<50,"moderate",IF(V9<75,"high","very high"))) -> very high
A10: ST3 | B10: Dayeuhkolot | C10: Kab. Bandung | D10: 54 | E10: urban domestic + industry | F10: 50.683333 | G10: 60.61 | H10: 50.43 | I10: 1.5143333 | J10: 2.134 | K10: 0.0963 | L10: 0.92 | M10: 441.6 | N10: 100 | O10: 100 | P10: 90 | Q10: 100 | R10: 0.3 | S10: 0.35 | T10: 0.2 | U10: 0.15 | V10: =$B$5*N10+$D$5*O10+$F$5*P10+$H$5*Q10 -> 98 | W10: =IF(V10<25,"low",IF(V10<50,"moderate",IF(V10<75,"high","very high"))) -> very high
A11: ST4 | B11: Nanjung - Bandung Barat | C11: Kab. Bandung Barat | D11: 71 | E11: mixed urban runoff | F11: 29.81 | G11: 42.51 | H11: 26.49 | I11: 0.891 | J11: 1.512 | K11: 0.0675 | L11: 0.78 | M11: 374.4 | N11: 90.7 | O11: 90.7 | P11: 72.5 | Q11: 86.2 | R11: 0.3 | S11: 0.35 | T11: 0.2 | U11: 0.15 | V11: =$B$5*N11+$D$5*O11+$F$5*P11+$H$5*Q11 -> 86.385 | W11: =IF(V11<25,"low",IF(V11<50,"moderate",IF(V11<75,"high","very high"))) -> very high
A12: ST5 | B12: Saguling reservoir inlet | C12: Kab. Bandung Barat | D12: 95 | E12: reservoir sedimentation | F12: 19.806667 | G12: 26.11 | H12: 20.69 | I12: 0.59166667 | J12: 0.92 | K12: 0.0415 | L12: 0.55 | M12: 264 | N12: 78 | O12: 77.2 | P12: 43.8 | Q12: 75.6 | R12: 0.3 | S12: 0.35 | T12: 0.2 | U12: 0.15 | V12: =$B$5*N12+$D$5*O12+$F$5*P12+$H$5*Q12 -> 70.52 | W12: =IF(V12<25,"low",IF(V12<50,"moderate",IF(V12<75,"high","very high"))) -> high
A13: ST6 | B13: Cirata reservoir | C13: Kab. Purwakarta | D13: 128 | E13: reservoir + aquaculture cages | F13: 14.566667 | G13: 22.63 | H13: 12.45 | I13: 0.43533333 | J13: 0.85 | K13: 0.0359 | L13: 0.66 | M13: 316.8 | N13: 74.2 | O13: 75.1 | P13: 57.5 | Q13: 67.7 | R13: 0.3 | S13: 0.35 | T13: 0.2 | U13: 0.15 | V13: =$B$5*N13+$D$5*O13+$F$5*P13+$H$5*Q13 -> 70.2 | W13: =IF(V13<25,"low",IF(V13<50,"moderate",IF(V13<75,"high","very high"))) -> high
A14: ST7 | B14: Jatiluhur outlet | C14: Kab. Purwakarta | D14: 158 | E14: reservoir outlet / raw water intake | F14: 9.4833333 | G14: 12.9 | H14: 9.5 | I14: 0.28333333 | J14: 0.484 | K14: 0.0205 | L14: 0.52 | M14: 249.6 | N14: 59.6 | O14: 59.9 | P14: 40 | Q14: 56.6 | R14: 0.3 | S14: 0.35 | T14: 0.2 | U14: 0.15 | V14: =$B$5*N14+$D$5*O14+$F$5*P14+$H$5*Q14 -> 55.335 | W14: =IF(V14<25,"low",IF(V14<50,"moderate",IF(V14<75,"high","very high"))) -> high
